#VRML_SIM R2020b utf8
WorldInfo {
  info [
    "Aldebaran's Nao H25 V5.0"
    "NAO is a programmable, 57-cm tall humanoid robot."
    "The body has 25 degrees of freedom (DOF)."
    "The sensors include 2 cameras, 4 microphones, sonar rangefinder, 2 IR emitters and receivers, 1 inertial board, and 8 pressure sensors."
  ]
  title "Aldebaran's Nao"
  basicTimeStep 20
  FPS 20
  coordinateSystem "NUE"
  contactProperties [
    ContactProperties {
      material1 "NAO foot material"
      coulombFriction [
        7
      ]
      bounce 0.3
      bounceVelocity 0.003
    }
  ]
}
Viewpoint {
  orientation -0.00014518873294013253 -0.9990409014664156 -0.043786483272845615 3.09905316196358
  position -0.43141966404982546 0.39926748141508916 -2.6676133655162366
}
TexturedBackground {
  texture "empty_office"
  skyColor [
    0.12549 0.290196 0.529412
  ]
}
TexturedBackgroundLight {
  texture "empty_office"
}
Floor {
  size 25 25
  tileSize 0.8 0.8
  appearance Parquetry {
  }
}
Solid {
  translation -0.27 0.05 -1.04
  children [
    Shape {
      appearance PBRAppearance {
      }
      geometry Box {
        size 0.1 0.1 0.1
      }
    }
  ]
}
Solid {
  translation -0.37 0.15 -1.04
  children [
    Shape {
      appearance PBRAppearance {
      }
      geometry Box {
        size 0.1 0.1 0.1
      }
    }
  ]
  name "solid(1)"
}
Solid {
  translation -0.37 0.05 -1.04
  children [
    Shape {
      appearance PBRAppearance {
      }
      geometry Box {
        size 0.1 0.1 0.1
      }
    }
  ]
  name "solid(3)"
}
Solid {
  translation -0.17 0.05 -1.04
  children [
    Shape {
      appearance PBRAppearance {
      }
      geometry Box {
        size 0.1 0.1 0.1
      }
    }
  ]
  name "solid(2)"
}
Solid {
  translation -0.47 0.15 -1.04
  children [
    Shape {
      appearance PBRAppearance {
      }
      geometry Box {
        size 0.1 0.1 0.1
      }
    }
  ]
  name "solid(4)"
}
Solid {
  translation -0.47 0.05 -1.04
  children [
    Shape {
      appearance PBRAppearance {
      }
      geometry Box {
        size 0.1 0.1 0.1
      }
    }
  ]
  name "solid(5)"
}
Solid {
  translation -0.57 0.05 -1.04
  children [
    Shape {
      appearance PBRAppearance {
      }
      geometry Box {
        size 0.1 0.1 0.1
      }
    }
  ]
  name "solid(8)"
}
Solid {
  translation -0.57 0.15 -1.04
  children [
    Shape {
      appearance PBRAppearance {
      }
      geometry Box {
        size 0.1 0.1 0.1
      }
    }
  ]
  name "solid(9)"
}
Solid {
  translation -0.27 0.15 -1.04
  children [
    Shape {
      appearance PBRAppearance {
      }
      geometry Box {
        size 0.1 0.1 0.1
      }
    }
  ]
  name "solid(6)"
}
Solid {
  translation -0.17 0.15 -1.04
  children [
    Shape {
      appearance PBRAppearance {
      }
      geometry Box {
        size 0.1 0.1 0.1
      }
    }
  ]
  name "solid(7)"
}
SolidBox {
  translation -0.21 0.25 -1.08
  size 0.1 0.1 0.01
  appearance PBRAppearance {
    baseColorMap ImageTexture {
      url [
        "../img/rock-03.jpg"
      ]
    }
    roughness 0.5
    metalness 0
  }
}
SolidBox {
  translation -0.38 0.25 -1.08
  name "box(1)"
  size 0.1 0.1 0.01
  appearance PBRAppearance {
    baseColorMap ImageTexture {
      url [
        "../img/SM-Papier.jpg"
      ]
    }
    roughness 0.5
    metalness 0
  }
}
SolidBox {
  translation -0.55 0.25 -1.08
  name "box(2)"
  size 0.1 0.1 0.01
  appearance PBRAppearance {
    baseColorMap ImageTexture {
      url [
        "../img/scissors2.jpg"
      ]
    }
    roughness 0.5
    metalness 0
  }
}
RobotisOp3 {
  hidden linearVelocity_0 1.4273309131502094e-05 4.358583987566062e-06 4.9425164703133695e-05
  hidden angularVelocity_0 0.00013700193246931258 -1.5208645420909345e-06 -4.450739676468789e-05
  hidden position_5_0 -2.222796928653781e-07
  hidden position_5_1 -2.654248547620449e-07
  hidden position_5_2 -1.038633032183032e-07
  hidden position_5_3 1.982474114135675e-07
  hidden position_5_4 -0.399986251806016
  hidden rotation_6 0 0 1 2.2302015940987725e-07
  hidden position_6_0 -1.9480331658883188e-07
  hidden linearVelocity_6 1.1173198360551261e-05 3.283435958864885e-06 3.8891551617236864e-05
  hidden angularVelocity_6 0.000137092552356251 7.206749829690507e-07 -4.4428633347125574e-05
  hidden rotation_7 1 0 0 1.954268969387413e-07
  hidden position_7_0 1.3166522481222302e-07
  hidden linearVelocity_7 9.911320550172547e-06 1.7370832794097614e-06 3.395904369875213e-05
  hidden angularVelocity_7 0.0001371881961104891 7.134807519881935e-07 -4.4358626717784044e-05
  hidden rotation_8 0 1 0 1.3328003749250115e-07
  hidden position_8_0 1.301126149486155e-07
  hidden linearVelocity_8 6.914118612315677e-06 4.8392977402238685e-06 2.3686065973517753e-05
  hidden angularVelocity_8 0.00013727226366048821 7.180137404506131e-07 -4.427197903787671e-05
  hidden rotation_9 0 1 0 1.2990531157078367e-07
  hidden position_9_0 -1.286131112721023e-07
  hidden linearVelocity_9 3.5186348335891886e-06 5.84822656686142e-06 1.2140350883528527e-05
  hidden angularVelocity_9 0.0001373362551647339 7.22583018638623e-07 -4.423905706576248e-05
  hidden rotation_10 0 1 0 1.2990531157078367e-07
  hidden position_10_0 1.7590536344824127e-07
  hidden linearVelocity_10 1.8254706415209187e-06 4.194095699932972e-06 5.8279304491198056e-06
  hidden angularVelocity_10 0.00013737795573246918 7.271816520196626e-07 -4.425853125214118e-05
  hidden rotation_11 1 0 0 1.7631291696726137e-07
  hidden linearVelocity_11 2.6803242423074787e-07 6.531461758966756e-06 -3.578391931934105e-08
  hidden angularVelocity_11 0.0001376353261630672 7.198079953081993e-07 -4.407183305987697e-05
  hidden rotation_12 0 0 1 2.6488883546935307e-07
  hidden position_12_0 2.5693355071372407e-07
  hidden linearVelocity_12 1.1207137441459695e-05 9.695734092489661e-06 3.906332427668785e-05
  hidden angularVelocity_12 0.0001370822324065199 1.079989584831025e-06 -4.443678684797078e-05
  hidden rotation_13 -1 0 0 2.563692708922217e-07
  hidden position_13_0 -1.0898304303452733e-07
  hidden linearVelocity_13 9.909117716399158e-06 8.291283438270676e-06 3.422768545776144e-05
  hidden angularVelocity_13 0.0001370980504639814 1.07118885655336e-06 -4.4423547988969636e-05
  hidden rotation_14 0 1 0 1.0745380149674385e-07
  hidden position_14_0 -1.1319877923909871e-07
  hidden linearVelocity_14 6.863918584952779e-06 1.142784211330965e-05 2.4071830318697686e-05
  hidden angularVelocity_14 0.00013714809783475228 1.0695431657440662e-06 -4.435608038781124e-05
  hidden rotation_15 0 1 0 1.1151007970493858e-07
  hidden position_15_0 1.1827032830234632e-07
  hidden linearVelocity_15 3.429656608994191e-06 1.2071447409786874e-05 1.2641742482881023e-05
  hidden angularVelocity_15 0.00013716111803055057 1.0679291993081638e-06 -4.4301978725760316e-05
  hidden rotation_16 0 1 0 1.1920928955078128e-07
  hidden position_16_0 -2.479028315960363e-07
  hidden linearVelocity_16 1.693026092331742e-06 1.1015096060192382e-05 6.429915364032749e-06
  hidden angularVelocity_16 0.00013713613134238401 1.0663582625468399e-06 -4.425743828335639e-05
  hidden rotation_17 -1 0 0 2.475566823160076e-07
  hidden linearVelocity_17 6.678970336811296e-08 1.5270500489718508e-05 6.868049789127037e-07
  hidden angularVelocity_17 0.0001370216391390678 1.0577196875578423e-06 -4.432449076578407e-05
  hidden rotation_18 0 -1 0 1.032382731180714e-07
  hidden position_18_0 1.482616291195373
  hidden linearVelocity_18 1.5713238371128527e-05 1.6865831968953042e-07 5.5847817540088594e-05
  hidden angularVelocity_18 0.00013738007885917184 -1.5210663375061089e-06 -4.554445125589746e-05
  hidden rotation_19 -1 0 0 1.4826162911953733
  hidden position_19_0 -1.126929305428348e-08
  hidden linearVelocity_19 0.006025700048189432 0.0001292349429249346 -0.00914465362198123
  hidden angularVelocity_19 0.18199794132109404 -0.00020476748868288215 0.11888451502891251
  hidden linearVelocity_20 0.02142317590213328 -0.00019453688226555172 -0.03271305026435641
  hidden angularVelocity_20 0.1819978841822441 -0.00020478159599209705 0.11888448279321867
  hidden rotation_21 0 -1 0 1.976862424823881e-07
  hidden position_21_0 -0.39998683358013665
  hidden linearVelocity_21 1.6259105105728318e-05 1.1839360774778387e-05 5.5360940165078885e-05
  hidden angularVelocity_21 0.00013810089630124752 -1.522181880085967e-06 -4.615813730272529e-05
  hidden rotation_22 0.9999999999999999 0 0 0.3999868335801368
  hidden position_22_0 2.7352001004940944e-08
  hidden linearVelocity_22 -0.00928655745507554 -0.04187013623960741 0.014201454757790742
  hidden angularVelocity_22 -0.836782639499388 0.0009676456243163222 -0.5473700278919728
  hidden rotation_23 1 0 0 2.9802322387695313e-08
  hidden linearVelocity_23 -0.03173881769183762 -0.15015108551486567 0.048333950123543516
  hidden angularVelocity_23 -0.8367826353122293 0.0009676527323535643 -0.5473700270015583
  hidden rotation_24 0 0 -1 0.3999862518060158
  hidden position_24_0 -0.49423518948393674
  hidden linearVelocity_24 0.0019401313748396043 3.979598556539603e-06 -0.0012600905437927616
  hidden angularVelocity_24 -0.0009954791147214548 -0.9999998790916156 -8.605709131498004e-05
  hidden rotation_25 0 1 0 0.4942351894839365
  hidden linearVelocity_25 0.01973099140334753 -0.0012186097150667968 -0.01594401354837605
  hidden angularVelocity_25 -0.06193019484087009 -1.0003419942776326 0.038539375259356544
  translation -0.40486278886597854 0.27869190746204214 -0.7716393238787866
  rotation -0.20578316975541777 0.6920704649830953 0.691875536887593 2.734175909522495
  leftFootSlot [
    Transform {
      translation 0.227054 -0.573275 0
      rotation 0.44721725566478654 0.7745924428183596 -0.44721725566478654 1.82348
      children [
        SliderJoint {
          jointParameters JointParameters {
            position 2.4719999999999804
          }
          device [
            LinearMotor {
              name "push_paper"
              maxPosition 2.485
            }
          ]
          endPoint Solid {
            translation -0.0209609 0.099895 -0.3089629999999999
            rotation -0.03961811632776106 0.9992148942337881 0 1.57079
            children [
              Shape {
                appearance PBRAppearance {
                  baseColorMap ImageTexture {
                    url [
                      "../img/SM-Papier.jpg"
                    ]
                  }
                  metalness 0
                  textureTransform TextureTransform {
                    rotation 4.75
                  }
                }
                geometry Box {
                  size 0.1 0.1 0.1
                }
              }
            ]
          }
        }
      ]
    }
    Transform {
      translation 0.227054 -0.573275 0
      rotation 0.44721725566478654 0.7745924428183596 -0.44721725566478654 1.82348
      children [
        SliderJoint {
          jointParameters JointParameters {
            position 2.4719999999999804
          }
          device [
            LinearMotor {
              name "push_scissors"
              maxPosition 2.48
            }
          ]
          endPoint Solid {
            translation -0.0220221 0.209882 -0.3100209999999999
            rotation -0.009647431607538996 0.999953462448817 0 1.5707896938995747
            children [
              Shape {
                appearance PBRAppearance {
                  baseColorMap ImageTexture {
                    url [
                      "../img/scissors2.jpg"
                    ]
                  }
                  metalness 0
                  textureTransform TextureTransform {
                    rotation 4.75
                  }
                }
                geometry Box {
                  size 0.1 0.1 0.1
                }
              }
            ]
          }
        }
      ]
    }
    Transform {
      children [
        SliderJoint {
          endPoint Solid {
            translation 0.153096 -0.2772 0.119988
            rotation 0 0.002299993916524136 0.9999973550104939 0.571011
            children [
              Shape {
                appearance PBRAppearance {
                  baseColorMap ImageTexture {
                    url [
                      "../img/choice.png"
                    ]
                    repeatS FALSE
                    repeatT FALSE
                  }
                }
                geometry Box {
                  size 0.2 0.1 0.1
                }
              }
            ]
          }
        }
      ]
    }
    Transform {
      translation 0.227054 -0.573275 0
      rotation 0.44721725566478654 0.7745924428183596 -0.44721725566478654 1.82348
      children [
        SliderJoint {
          jointParameters JointParameters {
            position 2.4719999999999804
          }
          device [
            LinearMotor {
              name "push_rock"
              maxPosition 2.48
            }
          ]
          endPoint Solid {
            translation -0.0199009 -0.00999907 -0.2979020000000001
            rotation -0.009647431607538996 0.999953462448817 0 1.5707896938995747
            children [
              Shape {
                appearance PBRAppearance {
                  baseColorMap ImageTexture {
                    url [
                      "../img/rock-03.jpg"
                    ]
                  }
                  metalness 0
                  textureTransform TextureTransform {
                    rotation 4.75
                  }
                }
                geometry Box {
                  size 0.1 0.1 0.1
                }
              }
            ]
          }
        }
      ]
    }
  ]
  controller "lying_nao"
}
