#VRML_SIM R2020b utf8
WorldInfo {
  info [
    "Aldebaran's Nao H25 V5.0"
    "NAO is a programmable, 57-cm tall humanoid robot."
    "The body has 25 degrees of freedom (DOF)."
    "The sensors include 2 cameras, 4 microphones, sonar rangefinder, 2 IR emitters and receivers, 1 inertial board, and 8 pressure sensors."
  ]
  title "Aldebaran's Nao"
  basicTimeStep 20
  FPS 20
  coordinateSystem "NUE"
  contactProperties [
    ContactProperties {
      material1 "NAO foot material"
      coulombFriction [
        7
      ]
      bounce 0.3
      bounceVelocity 0.003
    }
  ]
}
Viewpoint {
  orientation -5.2199638012706895e-05 -0.9926534782932193 -0.12099202166908077 3.1277421024735585
  position -0.3879246684939016 0.5351381991156268 -2.2421474518506614
}
TexturedBackground {
  texture "empty_office"
  skyColor [
    1 0.333333 1
  ]
}
TexturedBackgroundLight {
  texture "empty_office"
}
Floor {
  translation -0.43 0 -2.67
  size 4 7
  tileSize 0.8 0.8
  appearance Parquetry {
    type "light strip"
  }
}
Wall {
  translation 1.48 0 -1.10997
  rotation 0 1 0 1.5708
  name "wall(1)"
  size 4 2.4 0.2
}
Wall {
  translation -2.34 0 -1.09
  rotation 0 1 0 -1.5707953071795862
  name "wall(2)"
  size 4 2.4 0.2
}
Solid {
  translation -0.27 0.05 -1.04
  children [
    Shape {
      appearance PBRAppearance {
      }
      geometry Box {
        size 0.1 0.1 0.1
      }
    }
  ]
}
Solid {
  translation -0.37 0.15 -1.04
  children [
    Shape {
      appearance PBRAppearance {
      }
      geometry Box {
        size 0.1 0.1 0.1
      }
    }
  ]
  name "solid(1)"
}
Solid {
  translation -0.37 0.05 -1.04
  children [
    Shape {
      appearance PBRAppearance {
      }
      geometry Box {
        size 0.1 0.1 0.1
      }
    }
  ]
  name "solid(3)"
}
Solid {
  translation -0.17 0.05 -1.04
  children [
    Shape {
      appearance PBRAppearance {
      }
      geometry Box {
        size 0.1 0.1 0.1
      }
    }
  ]
  name "solid(2)"
}
Solid {
  translation -0.47 0.15 -1.04
  children [
    Shape {
      appearance PBRAppearance {
      }
      geometry Box {
        size 0.1 0.1 0.1
      }
    }
  ]
  name "solid(4)"
}
Solid {
  translation -0.47 0.05 -1.04
  children [
    Shape {
      appearance PBRAppearance {
      }
      geometry Box {
        size 0.1 0.1 0.1
      }
    }
  ]
  name "solid(5)"
}
Solid {
  translation -0.57 0.05 -1.04
  children [
    Shape {
      appearance PBRAppearance {
      }
      geometry Box {
        size 0.1 0.1 0.1
      }
    }
  ]
  name "solid(8)"
}
Solid {
  translation -0.57 0.15 -1.04
  children [
    Shape {
      appearance PBRAppearance {
      }
      geometry Box {
        size 0.1 0.1 0.1
      }
    }
  ]
  name "solid(9)"
}
Solid {
  translation -0.27 0.15 -1.04
  children [
    Shape {
      appearance PBRAppearance {
      }
      geometry Box {
        size 0.1 0.1 0.1
      }
    }
  ]
  name "solid(6)"
}
Solid {
  translation -0.17 0.15 -1.04
  children [
    Shape {
      appearance PBRAppearance {
      }
      geometry Box {
        size 0.1 0.1 0.1
      }
    }
  ]
  name "solid(7)"
}
SolidBox {
  translation -0.21 0.25 -1.08
  size 0.1 0.1 0.01
  appearance PBRAppearance {
    baseColorMap ImageTexture {
      url [
        "../img/rock-03.jpg"
      ]
    }
    roughness 0.5
    metalness 0
  }
}
SolidBox {
  translation -0.38 0.25 -1.08
  name "box(1)"
  size 0.1 0.1 0.01
  appearance PBRAppearance {
    baseColorMap ImageTexture {
      url [
        "../img/SM-Papier.jpg"
      ]
    }
    roughness 0.5
    metalness 0
  }
}
SolidBox {
  translation -0.55 0.25 -1.08
  name "box(2)"
  size 0.1 0.1 0.01
  appearance PBRAppearance {
    baseColorMap ImageTexture {
      url [
        "../img/scissors2.jpg"
      ]
    }
    roughness 0.5
    metalness 0
  }
}
RobotisOp3 {
  translation -0.40486278886597854 0.27869190746204214 -0.7716393238787866
  rotation -0.20578316975541777 0.6920704649830953 0.691875536887593 2.734175909522495
  controller "lying_robot"
  leftFootSlot [
    Transform {
      translation 0.227054 -0.573275 0
      rotation 0.44721725566478654 0.7745924428183596 -0.44721725566478654 1.6925803061004252
      children [
        SliderJoint {
          jointParameters JointParameters {
            position 2.4719999999999804
          }
          device [
            LinearMotor {
              name "push_paper"
              maxPosition 2.55
            }
          ]
          endPoint Solid {
            translation -0.0397131 0.0999959 -0.29212700000000025
            rotation 0 0.9578262616707715 -0.2873479640676002 0.1
            children [
              Shape {
                appearance PBRAppearance {
                  baseColorMap ImageTexture {
                    url [
                      "../img/SM-Papier.jpg"
                    ]
                  }
                  metalness 0
                  textureTransform TextureTransform {
                    rotation 4.75
                  }
                }
                geometry Box {
                  size 0.1 0.1 0.1
                }
              }
            ]
          }
        }
      ]
    }
    Transform {
      translation 0.227054 -0.573275 0
      rotation 0.44721725566478654 0.7745924428183596 -0.44721725566478654 1.82348
      children [
        SliderJoint {
          jointParameters JointParameters {
            position 2.4719999999999804
          }
          device [
            LinearMotor {
              name "push_scissors"
              maxPosition 2.48
            }
          ]
          endPoint Solid {
            translation -0.0224081 0.249878 -0.3104049999999998
            rotation -0.009647431607538996 0.999953462448817 0 1.5707896938995747
            children [
              Shape {
                appearance PBRAppearance {
                  baseColorMap ImageTexture {
                    url [
                      "../img/scissors2.jpg"
                    ]
                  }
                  metalness 0
                  textureTransform TextureTransform {
                    rotation 4.75
                  }
                }
                geometry Box {
                  size 0.1 0.1 0.1
                }
              }
            ]
          }
        }
      ]
    }
    Transform {
      children [
        SliderJoint {
          endPoint Solid {
            translation 0.153096 -0.2772 0.119988
            rotation 0 0.002299993916524136 0.9999973550104939 0.571011
            children [
              Shape {
                appearance PBRAppearance {
                  baseColorMap ImageTexture {
                    url [
                      "../img/choice.png"
                    ]
                    repeatS FALSE
                    repeatT FALSE
                  }
                }
                geometry Box {
                  size 0.2 0.1 0.1
                }
              }
            ]
          }
        }
      ]
    }
    Transform {
      translation 0.227054 -0.573275 0
      rotation 0.44721725566478654 0.7745924428183596 -0.44721725566478654 1.82348
      children [
        SliderJoint {
          jointParameters JointParameters {
            position 2.4719999999999804
          }
          device [
            LinearMotor {
              name "push_rock"
              maxPosition 2.49
            }
          ]
          endPoint Solid {
            translation -0.0191291 -0.0899918 -0.29713199999999995
            rotation -0.009647431607538996 0.999953462448817 0 1.5707896938995747
            children [
              Shape {
                appearance PBRAppearance {
                  baseColorMap ImageTexture {
                    url [
                      "../img/rock-03.jpg"
                    ]
                  }
                  metalness 0
                  textureTransform TextureTransform {
                    rotation 4.75
                  }
                }
                geometry Box {
                  size 0.1 0.1 0.1
                }
              }
            ]
          }
        }
      ]
    }
  ]
}
Wall {
  translation -0.43 0 0.83
  size 4 2.4 0.2
}
